<?xml version="1.0"?>
<robot name="my_bot">
  <!-- Base link -->
  <link name="base_link">
    <visual>
      <geometry>
        <box size="0.6 0.3 0.05"/>
      </geometry>
      <material name="gray">
        <color rgba="0.5 0.5 0.5 1.0"/>
      </material>
    </visual>
    <collision>
      <geometry>
        <box size="1.0 0.3 0.05"/>
      </geometry>
    </collision>
    <inertial>
      <mass value="5.0"/>
      <inertia ixx="0.1" ixy="0.0" ixz="0.0"
               iyy="0.1" iyz="0.0"
               izz="0.1"/>
    </inertial>
  </link>

  <!-- Link for the laser -->
  <link name="laser_link">
    <inertial>
      <mass value="0.1"/>
      <origin xyz="0 0 0" rpy="0 0 0"/>
      <inertia ixx="0.01" ixy="0" ixz="0" iyy="0.01" iyz="0" izz="0.01"/>
    </inertial>
    <visual>
      <geometry>
        <cylinder length="0.05" radius="0.02"/>
      </geometry>
    </visual>
    <collision>
      <geometry>
        <cylinder length="0.05" radius="0.02"/>
      </geometry>
    </collision>
  </link>

  <!-- Gazebo sensor plugin for laser_link -->
  <gazebo reference="laser_link">
    <sensor type="ray" name="laser">
      <pose>0 0 0.1 0 0 0</pose>
      <visualize>true</visualize>
      <update_rate>10.0</update_rate>
      <ray>
        <scan>
          <horizontal>
            <samples>720</samples>
            <resolution>1</resolution>
            <min_angle>-1.57</min_angle>
            <max_angle>1.57</max_angle>
          </horizontal>
        </scan>
        <range>
          <min>0.1</min>
          <max>10.0</max>
        </range>
        <noise>
          <type>gaussian</type>
          <mean>0.0</mean>
          <stddev>0.01</stddev>
        </noise>
      </ray>
      <plugin name="gazebo_ros_laser_controller" filename="libgazebo_ros_laser.so">
        <topicName>/scan</topicName>
        <frameName>laser_link</frameName>
      </plugin>
    </sensor>
  </gazebo>

  <!-- Joint to attach laser to base_link -->
  <joint name="laser_joint" type="fixed">
    <parent link="base_link"/>
    <child link="laser_link"/>
    <origin xyz="0 0 0.3" rpy="0 0 0"/>
  </joint>

  <!-- Left wheel -->
  <link name="left_wheel">
    <visual>
      <geometry>
        <cylinder length="0.05" radius="0.1"/>
      </geometry>
      <origin rpy="1.5708 0 0" xyz="0 0 0"/>
      <material name="black">
        <color rgba="0.1 0.1 0.1 1"/>
      </material>
    </visual>
    <collision>
      <origin rpy="1.5708 0 0" xyz="0 0 0"/>
      <geometry>
        <cylinder length="0.05" radius="0.1"/>
      </geometry>
    </collision>
    <inertial>
      <mass value="0.5"/>
      <inertia ixx="0.001" ixy="0.0" ixz="0.0"
               iyy="0.001" iyz="0.0"
               izz="0.001"/>
    </inertial>
  </link>

  <!-- Right wheel -->
  <link name="right_wheel">
    <visual>
      <geometry>
        <cylinder length="0.05" radius="0.1"/>
      </geometry>
      <origin rpy="1.5708 0 0" xyz="0 0 0"/>
      <material name="black"/>
    </visual>
    <collision>
      <origin rpy="1.5708 0 0" xyz="0 0 0"/>
      <geometry>
        <cylinder length="0.05" radius="0.1"/>
      </geometry>
    </collision>
    <inertial>
      <mass value="0.5"/>
      <inertia ixx="0.001" ixy="0.0" ixz="0.0"
               iyy="0.001" iyz="0.0"
               izz="0.001"/>
    </inertial>
  </link>

  <!-- Joints: Placing both wheels close to one end of the plank -->
  <joint name="left_wheel_joint" type="continuous">
    <parent link="base_link"/>
    <child link="left_wheel"/>
    <origin xyz="-0.3 0.2 0.025" rpy="0 0 0"/>
    <axis xyz="0 1 0"/>
  </joint>

  <joint name="right_wheel_joint" type="continuous">
    <parent link="base_link"/>
    <child link="right_wheel"/>
    <origin xyz="-0.3 -0.2 0.025" rpy="0 0 0"/>
    <axis xyz="0 1 0"/>
  </joint>

  <!-- Gazebo plugin to simulate differential drive -->
  <gazebo>
  <plugin name="diff_drive_controller" filename="libgazebo_ros_diff_drive.so">
    <ros>
      <namespace>/</namespace>
      <remapping>cmd_vel:=cmd_vel</remapping>
      <remapping>odom:=odom</remapping>
    </ros>
    <leftJoint>left_wheel_joint</leftJoint>
    <rightJoint>right_wheel_joint</rightJoint>
    <wheelSeparation>0.4</wheelSeparation>
    <wheelDiameter>0.2</wheelDiameter>
    <publishWheelTF>true</publishWheelTF>
    <publishOdomTF>true</publishOdomTF>
    <publishWheelJointState>true</publishWheelJointState>
    <robotBaseFrame>base_link</robotBaseFrame>
    <odometryFrame>odom</odometryFrame>
    <odometryTopic>odom</odometryTopic>
    <commandTopic>cmd_vel</commandTopic>
    <updateRate>50.0</updateRate>
  </plugin>
  <plugin name="gazebo_ros_control" filename="libgazebo_ros_control.so"/>
</gazebo>
</robot>

